
The base dimension of your u-net should ideally be no smaller than 128, as recommended by a professional DDPM trainer https://nonint.com/2022/05/04/friends-dont-let-friends-train-small-diffusion-models/
Epoch 1/8
--- Unet 1 ---
<torch.utils.data.dataloader.DataLoader object at 0x7f2982ab1070>













Train Step 14/40736 --- Loss: 0.6197
Traceback (most recent call last):
  File "/home/azureuser/imagen/spaceforge/train.py", line 269, in <module>
    run_train_loop(cfg, trainer, loader, device, i=cfg["train"]["unet_number"])
  File "/home/azureuser/imagen/spaceforge/train.py", line 144, in run_train_loop
    train(cfg, dataloader, trainer, epoch, i, device)
  File "/home/azureuser/imagen/spaceforge/train.py", line 68, in train
    for step, batch in enumerate(dataloader):
  File "/home/azureuser/miniconda3/envs/imagen/lib/python3.9/site-packages/torch/utils/data/dataloader.py", line 681, in __next__
    data = self._next_data()
  File "/home/azureuser/miniconda3/envs/imagen/lib/python3.9/site-packages/torch/utils/data/dataloader.py", line 1356, in _next_data
    return self._process_data(data)
  File "/home/azureuser/miniconda3/envs/imagen/lib/python3.9/site-packages/torch/utils/data/dataloader.py", line 1402, in _process_data
    data.reraise()
  File "/home/azureuser/miniconda3/envs/imagen/lib/python3.9/site-packages/torch/_utils.py", line 461, in reraise
    raise exception
FileNotFoundError: Caught FileNotFoundError in DataLoader worker process 14.
Original Traceback (most recent call last):
  File "/home/azureuser/miniconda3/envs/imagen/lib/python3.9/site-packages/torch/utils/data/_utils/worker.py", line 302, in _worker_loop
    data = fetcher.fetch(index)
  File "/home/azureuser/miniconda3/envs/imagen/lib/python3.9/site-packages/torch/utils/data/_utils/fetch.py", line 32, in fetch
    data.append(next(self.dataset_iter))
  File "/home/azureuser/miniconda3/envs/imagen/lib/python3.9/site-packages/webdataset/pipeline.py", line 68, in iterator
    for sample in self.iterator1():
  File "/home/azureuser/miniconda3/envs/imagen/lib/python3.9/site-packages/webdataset/filters.py", line 382, in _to_tuple
    for sample in data:
  File "/home/azureuser/miniconda3/envs/imagen/lib/python3.9/site-packages/webdataset/filters.py", line 359, in _map_dict
    for sample in data:
  File "/home/azureuser/miniconda3/envs/imagen/lib/python3.9/site-packages/webdataset/filters.py", line 316, in _rename
    for sample in data:
  File "/home/azureuser/miniconda3/envs/imagen/lib/python3.9/site-packages/webdataset/filters.py", line 296, in _map
    for sample in data:
  File "/home/azureuser/miniconda3/envs/imagen/lib/python3.9/site-packages/webdataset/filters.py", line 207, in _shuffle
    for sample in data:
  File "/home/azureuser/miniconda3/envs/imagen/lib/python3.9/site-packages/webdataset/tariterators.py", line 152, in group_by_keys
    for filesample in data:
  File "/home/azureuser/miniconda3/envs/imagen/lib/python3.9/site-packages/webdataset/tariterators.py", line 126, in tar_file_expander
    for source in data:
  File "/home/azureuser/miniconda3/envs/imagen/lib/python3.9/site-packages/webdataset/tariterators.py", line 75, in url_opener
    if handler(exn):
  File "/home/azureuser/miniconda3/envs/imagen/lib/python3.9/site-packages/webdataset/filters.py", line 79, in reraise_exception
    raise exn
  File "/home/azureuser/miniconda3/envs/imagen/lib/python3.9/site-packages/webdataset/tariterators.py", line 70, in url_opener
    stream = gopen.gopen(url, **kw)
  File "/home/azureuser/miniconda3/envs/imagen/lib/python3.9/site-packages/webdataset/gopen.py", line 374, in gopen
    return open(url, mode, buffering=bufsize)
FileNotFoundError: [Errno 2] No such file or directory: '/datadrive4T/cc12m_w_embeds/00902.tar'