Epoch 1/8
--- Unet 1 ---
<torch.utils.data.dataloader.DataLoader object at 0x7febda6763d0>
Traceback (most recent call last):
  File "/home/azureuser/imagen/spaceforge/train.py", line 290, in <module>
    run_train_loop(cfg, trainer, loader, device, i=cfg["train"]["unet_number"])
  File "/home/azureuser/imagen/spaceforge/train.py", line 148, in run_train_loop
    train(cfg, dataloader, trainer, epoch, unet_num, device)
  File "/home/azureuser/imagen/spaceforge/train.py", line 69, in train
    for step, batch in enumerate(dataloader):
  File "/home/azureuser/miniconda3/envs/imagen/lib/python3.9/site-packages/torch/utils/data/dataloader.py", line 681, in __next__
    data = self._next_data()
  File "/home/azureuser/miniconda3/envs/imagen/lib/python3.9/site-packages/torch/utils/data/dataloader.py", line 1376, in _next_data
    return self._process_data(data)
  File "/home/azureuser/miniconda3/envs/imagen/lib/python3.9/site-packages/torch/utils/data/dataloader.py", line 1402, in _process_data
    data.reraise()
  File "/home/azureuser/miniconda3/envs/imagen/lib/python3.9/site-packages/torch/_utils.py", line 461, in reraise
    raise exception
ValueError: Caught ValueError in DataLoader worker process 0.
Original Traceback (most recent call last):
  File "/home/azureuser/miniconda3/envs/imagen/lib/python3.9/site-packages/torch/utils/data/_utils/worker.py", line 302, in _worker_loop
    data = fetcher.fetch(index)
  File "/home/azureuser/miniconda3/envs/imagen/lib/python3.9/site-packages/torch/utils/data/_utils/fetch.py", line 32, in fetch
    data.append(next(self.dataset_iter))
  File "/home/azureuser/miniconda3/envs/imagen/lib/python3.9/site-packages/webdataset/pipeline.py", line 68, in iterator
    for sample in self.iterator1():
  File "/home/azureuser/miniconda3/envs/imagen/lib/python3.9/site-packages/webdataset/filters.py", line 382, in _to_tuple
    for sample in data:
  File "/home/azureuser/miniconda3/envs/imagen/lib/python3.9/site-packages/webdataset/filters.py", line 359, in _map_dict
    for sample in data:
  File "/home/azureuser/miniconda3/envs/imagen/lib/python3.9/site-packages/webdataset/filters.py", line 330, in _rename
    if handler(exn):
  File "/home/azureuser/miniconda3/envs/imagen/lib/python3.9/site-packages/webdataset/filters.py", line 79, in reraise_exception
    raise exn
  File "/home/azureuser/miniconda3/envs/imagen/lib/python3.9/site-packages/webdataset/filters.py", line 327, in _rename
    result.update({k: getfirst(sample, v, missing_is_error=True) for k, v in kw.items()})
  File "/home/azureuser/miniconda3/envs/imagen/lib/python3.9/site-packages/webdataset/filters.py", line 327, in <dictcomp>
    result.update({k: getfirst(sample, v, missing_is_error=True) for k, v in kw.items()})
  File "/home/azureuser/miniconda3/envs/imagen/lib/python3.9/site-packages/webdataset/filters.py", line 116, in getfirst
    raise ValueError(f"didn't find {keys} in {list(a.keys())}")
ValueError: didn't find ['emb.pyd'] in ['__key__', '__url__', 'npy', 'png', 'txt']